Workbook

Sheet note
A1: Ipotesi di base utilizzate nel modello
A2: Non è prevista la distribuzione degli utili in nessuno degli anni considerati
A3: L'iva si considera liquidata entro l'anno la fine dell'anno di competenza
A4: Le imposte si considerano liquidate entro la fine dell'anno di competenza
A5: I costi di personale sono considerati per semplicità comprensivi di TFR
A6: Gli investimenti considerati sono di tipo immateriale con ammortamento in 5 anni

Sheet Conto Economico
A1: CONTO ECONOMICO
A3: RICAVI | D3: Y1 | E3: Y2 | F3: Y3 | G3: Y4 | H3: Y5
A4: Servizi
A5: Lezioni Online | D5: 1200 | E5: 2000 | F5: 10000 | G5: 30000 | H5: 70000
A6: Lezioni in Presenza | D6: 800 | E6: 1200 | F6: 2400 | G6: 6000 | H6: 16000
A8: TOTALE UTENTI | D8: =SUM(D5:D7) -> 2000 | E8: =SUM(E5:E7) -> 3200 | F8: =SUM(F5:F7) -> 12400 | G8: =SUM(G5:G7) -> 36000 | H8: =SUM(H5:H7) -> 86000
B9: Ricavo unitario | C9: Media Lezioni
A10: ARPU Lezioni Online | B10: 4 | C10: 15 | D10: =C10*B10 -> 60 | E10: =C10*B10 -> 60 | F10: =C10*B10 -> 60 | G10: =C10*B10 -> 60 | H10: =C10*B10 -> 60
A11: ARPU Lezioni in Presenza | B11: 6 | C11: 10 | D11: =C11*B11 -> 60 | E11: =C11*B11 -> 60 | F11: =C11*B11 -> 60 | G11: =C11*B11 -> 60 | H11: =C11*B11 -> 60
B12: Media Accessi | C12: =C11+C10 -> 25
A13: ARPU Pubblicità (Pay-per-impression) | B13: 0.01 | D13: =B13*D8*C12 -> 500 | E13: =B13*E8*C12 -> 800 | F13: =B13*F8*C12 -> 3100 | G13: =B13*G8*C12 -> 9000 | H13: =B13*H8*C12 -> 21500
A15: Ricavi da servizio 1 | D15: =$D5*D10 -> 72000 | E15: =$E5*E10 -> 120000 | F15: =$F5*F10 -> 600000 | G15: =$G5*G10 -> 1800000 | H15: =$H5*H10 -> 4200000
A16: Ricavi da servizio 2 | D16: =$D6*D11 -> 48000 | E16: =$E6*E11 -> 72000 | F16: =$F6*F11 -> 144000 | G16: =$G6*G11 -> 360000 | H16: =$H6*H11 -> 960000
A17: TOTALE RICAVI | D17: =SUM(D15:D16) + D13 -> 120500 | E17: =SUM(E15:E16) + E13 -> 192800 | F17: =SUM(F15:F16) + F13 -> 747100 | G17: =SUM(G15:G16) + G13 -> 2169000 | H17: =SUM(H15:H16) + H13 -> 5181500
A19: COSTI | D19: Y1 | E19: Y2 | F19: Y3 | G19: Y4 | H19: Y5
A20: COSTI VARIABILI OPERATIVI | B20: Costo unitario
A21: Costi variabili cloud | B21: 0.7 | D21: =D8*$B21 -> 1400 | E21: =E8*$B21 -> 2240 | F21: =F8*$B21 -> 8680 | G21: =G8*$B21 -> 25200 | H21: =H8*$B21 -> 60200
A22: Costi variabili supporto clienti | B22: 1 | D22: =D8*$B22 -> 2000 | E22: =E8*$B22 -> 3200 | F22: =F8*$B22 -> 12400 | G22: =G8*$B22 -> 36000 | H22: =H8*$B22 -> 86000
A24: TOTALE COSTI VARIABILI | D24: =+D21+D22 -> 3400 | E24: =+E22+E21 -> 5440 | F24: =+F22+F21 -> 21080 | G24: =+G22+G21 -> 61200 | H24: =+H21+H22 -> 146200
A26: COSTI FISSI OPERATIVI
A27: Personale | D27: 200000 | E27: 240000 | F27: 270000 | G27: 300000 | H27: 350000
A28: Canoni (affitto locali, utenze, ecc.) | D28: 15600 | E28: 15600 | F28: 15600 | G28: 20000 | H28: 25000
A29: Spese generali | D29: 9400 | E29: 9400 | F29: 9400 | G29: 15000 | H29: 20000
A30: Consulenze | D30: 15000 | E30: 15000 | F30: 20000 | G30: 20000 | H30: 40000
A31: Marketing | D31: 70000 | E31: 80000 | F31: 90000 | G31: 100000 | H31: 120000
A32: Spese commerciali | B32: Dei ricavi: | C32: 0.02 | D32: =C32*D17 -> 2410 | E32: =C32*E17 -> 3856 | F32: =C32*F17 -> 14942 | G32: =C32*G17 -> 43380 | H32: =C32*H17 -> 103630
A33: Altri costi | D33: 6500 | E33: 6500 | F33: 6500 | G33: 8000 | H33: 10000
A34: TOTALE COSTI FISSI OPERATIVI | D34: =SUM(D27:D33) -> 318910 | E34: =SUM(E27:E33) -> 370356 | F34: =SUM(F27:F33) -> 426442 | G34: =SUM(G27:G33) -> 506380 | H34: =SUM(H27:H33) -> 668630
A36: EBITDA ( = Ricavi - Costi) | D36: =D17-D24-D34 -> -201810 | E36: =E17-E24-E34 -> -182996 | F36: =F17-F24-F34 -> 299578 | G36: =G17-G24-G34 -> 1601420 | H36: =H17-H24-H34 -> 4366670
A39: Ammortamenti (D&A) | D39: =+D70 -> 14800 | E39: =+E70 -> 24800 | F39: =+F70 -> 24800 | G39: =+G70 -> 24800 | H39: =+H70 -> 24800
A40: EBIT ( = EBITDA - D&A) | D40: =+D36-D39 -> -216610 | E40: =+E36-E39 -> -207796 | F40: =+F36-F39 -> 274778 | G40: =+G36-G39 -> 1576620 | H40: =+H36-H39 -> 4341870
A41: Ebit margin % | D41: =D40/D17 -> -1.7975934 | E41: =E40/E17 -> -1.0777801 | F41: =F40/F17 -> 0.3677928 | G41: =G40/G17 -> 0.72688797 | H41: =H40/H17 -> 0.83795619
A43: TASSE | B43: 0.32 | D43: =-IF(D40<0,0,D40*B43) -> 0 | E43: =-IF(E40<0,0,E40*$B43) -> 0 | F43: =-IF(F40<0,0,F40*$B43) -> -87928.96 | G43: =-IF(G40<0,0,G40*$B43) -> -504518.4 | H43: =-IF(H40<0,0,H40*$B43) -> -1389398.4
A45: UTILE/PERDITA D'ESERCIZIO | D45: =+D40+D43 -> -216610 | E45: =+E40+E43 -> -207796 | F45: =+F40+F43 -> 186849.04 | G45: =+G40+G43 -> 1072101.6 | H45: =+H40+H43 -> 2952471.6
D47: Y1 | E47: Y2 | F47: Y3 | G47: Y4 | H47: Y5
A48: Investimenti ammortizzabili
A49: Investimenti anno 1
A50: Infrastrutture tecnologiche | D50: 10000
A51: Software e licenze | D51: 15000
A52: Workstation (composta da pc, schermi e sistemi operativi) | D52: 6000
...

Sheet cash flow
A2: CASH FLOW
B3: Y1 | C3: Y2 | D3: Y3 | E3: Y4 | F3: Y5
A4: INVESTIMENTI
A5: uscita per investimenti | B5: =-'Conto Economico'!D62 -> -74000 | C5: =-'Conto Economico'!E62 -> -50000 | D5: =-'Conto Economico'!F62 -> 0 | E5: =-'Conto Economico'!G62 -> 0 | F5: =-'Conto Economico'!H62 -> 0
A6: uscita per IVA investimenti | B6: =+B5*0.22 -> -16280 | C6: =+C5*0.22 -> -11000 | D6: =+D5*0.22 -> 0 | E6: =+E5*0.22 -> 0 | F6: =+F5*0.22 -> 0
A7: A - TOTALE INVESTIMENTI | B7: =SUM(B5:B6) -> -90280 | C7: =SUM(C5:C6) -> -61000 | D7: =SUM(D5:D6) -> 0 | E7: =SUM(E5:E6) -> 0 | F7: =SUM(F5:F6) -> 0
A9: GESTIONE FINANZIARIA
A10: Mezzi propri per fase 1 | B10: 50000
A11: Investimenti da terzi | B11: 250000 | C11: 300000
A12: entrata da finanziamento a breve
A13: interessi sul finanziamento a breve
A14: uscita per restituzione finanziamento a breve
A15: B - TOTALE GESTIONE FINANZIARIA | B15: =SUM(B9:B14) -> 300000 | C15: =SUM(C9:C14) -> 300000 | D15: =SUM(D9:D14) -> 0 | E15: =SUM(E9:E14) -> 0 | F15: =SUM(F9:F14) -> 0
A17: GESTIONE OPERATIVA
A18: Entrate da ricavi | B18: =+'Conto Economico'!D17 -> 120500 | C18: =+'Conto Economico'!E17 -> 192800 | D18: =+'Conto Economico'!F17 -> 747100 | E18: =+'Conto Economico'!G17 -> 2169000 | F18: =+'Conto Economico'!H17 -> 5181500
A19: IVA sui ricavi | B19: =+B18*22% -> 26510 | C19: =+C18*22% -> 42416 | D19: =+D18*22% -> 164362 | E19: =+E18*22% -> 477180 | F19: =+F18*22% -> 1139930
A20: Costi operativi | B20: =-'Conto Economico'!D24-'Conto Economico'!D34 -> -322310 | C20: =-'Conto Economico'!E24-'Conto Economico'!E34 -> -375796 | D20: =-'Conto Economico'!F24-'Conto Economico'!F34 -> -447522 | E20: =-'Conto Economico'!G24-'Conto Economico'!G34 -> -567580 | F20: =-'Conto Economico'!H24-'Conto Economico'!H34 -> -814830
A21: IVA sui costi operativi | B21: =(+B20+'Conto Economico'!D27)*0.22 -> -26908.2 | C21: =(+C20+'Conto Economico'!E27)*0.22 -> -29875.12 | D21: =(+D20+'Conto Economico'!F27)*0.22 -> -39054.84 | E21: =+(E20+'Conto Economico'!G27)*22% -> -58867.6 | F21: =+(F20+'Conto Economico'!H27)*22% -> -102262.6
A22: saldo IVA | B22: =-IF(B46<0,0,B46) -> 0 | C22: =-IF(C46<0,0,C46) -> 0 | D22: =-IF(D46<0,0,D46) -> -110169.84 | E22: =-IF(E46<0,0,E46) -> -418312.4 | F22: =-IF(F46<0,0,F46) -> -1037667.4
A23: C - TOTALE GESTIONE OPERATIVA | B23: =SUM(B16:B22) -> -202208.2 | C23: =SUM(C16:C22) -> -170455.12 | D23: =SUM(D16:D22) -> 314715.32 | E23: =SUM(E16:E22) -> 1601420 | F23: =SUM(F16:F22) -> 4366670
A25: Flusso di cassa operativo | B25: =+B7+B23 -> -292488.2 | C25: =+C7+C23 -> -231455.12 | D25: =+D7+D23 -> 314715.32 | E25: =+E7+E23 -> 1601420 | F25: =+F7+F23 -> 4366670
A26: Tasse (IRES e IRAP) | B26: =+'Conto Economico'!D43 -> 0 | C26: =+'Conto Economico'!E43 -> 0 | D26: =+'Conto Economico'!F43 -> -87928.96 | E26: =+'Conto Economico'!G43 -> -504518.4 | F26: =+'Conto Economico'!H43 -> -1389398.4
A27: Flusso di cassa netto | B27: =+B25+B26 -> -292488.2 | C27: =+C25+C26 -> -231455.12 | D27: =+D25+D26 -> 226786.36 | E27: =+E25+E26 -> 1096901.6 | F27: =+F25+F26 -> 2977271.6
A29: FLUSSO DI CASSA TOTALE | B29: =+B23+B15+B7+B26 -> 7511.8 | C29: =+C23+C15+C7+C26 -> 68544.88 | D29: =+D23+D15+D7+D26 -> 226786.36 | E29: =+E23+E15+E7+E26 -> 1096901.6 | F29: =+F23+F15+F7+F26 -> 2977271.6
A31: FLUSSO DI CASSA CUMULATO | B31: =+B29 -> 7511.8 | C31: =+C29+B31 -> 76056.68 | D31: =+D29+C31 -> 302843.04 | E31: =+E29+D31 -> 1399744.6 | F31: =+F29+E31 -> 4377016.2
A37: IVA
A38: IVA su investimenti | B38: =-B6 -> 16280 | C38: =-C6 -> 11000 | D38: =-D6 -> 0 | E38: =-E6 -> 0 | F38: =-F6 -> 0
A39: IVA su costi operativi | B39: =-B21 -> 26908.2 | C39: =-C21 -> 29875.12 | D39: =-D21 -> 39054.84 | E39: =-E21 -> 58867.6 | F39: =-F21 -> 102262.6
A40: Totale IVA | B40: =SUM(B38:B39) -> 43188.2 | C40: =SUM(C38:C39) -> 40875.12 | D40: =SUM(D38:D39) -> 39054.84 | E40: =SUM(E38:E39) -> 58867.6 | F40: =SUM(F38:F39) -> 102262.6
A42: IVA su ricavi | B42: =+B19 -> 26510 | C42: =+C19 -> 42416 | D42: =+D19 -> 164362 | E42: =+E19 -> 477180 | F42: =+F19 -> 1139930
A44: Bilancio annuale IVA | B44: =+B42-B40 -> -16678.2 | C44: =+C42-C40 -> 1540.88 | D44: =+D42-D40 -> 125307.16 | E44: =+E42-E40 -> 418312.4 | F44: =+F42-F40 -> 1037667.4
A46: Bilancio totale IVA | B46: =+B44 -> -16678.2 | C46: =+IF(B46<0,B46+C44,C44) -> -15137.32 | D46: =+IF(C46<0,C46+D44,D44) -> 110169.84 | E46: =+IF(D46<0,D46+E44,E44) -> 418312.4 | F46: =+IF(E46<0,E46+F44,F44) -> 1037667.4
